<?xml version="1.0" encoding="utf-8"?>
<!-- This URDF was automatically created by SolidWorks to URDF Exporter! Originally created by Stephen Brawner (brawner@gmail.com) 
     Commit Version: 1.6.0-4-g7f85cfe  Build Version: 1.6.7995.38578
     For more information, please see http://wiki.ros.org/sw_urdf_exporter -->
<robot name="manip">

  <link name="world"/>
	<joint name="fixed" type="fixed">
		<parent link="world"/>
		<child link="base_link"/>
		
	</joint>
  <link name="base_link">
    <inertial>
      <origin
        xyz="7.5955E-15 4.0463E-17 0.01"
        rpy="0 0 0" />
      <mass
        value="3.1366" />
      <inertia
        ixx="0.0051231"
        ixy="1.3046E-29"
        ixz="3.7324E-15"
        iyy="0.0051231"
        iyz="1.7109E-17"
        izz="0.010037" />
    </inertial>
    <visual>
      <origin
        xyz="0 0 0"
        rpy="0 0 0" />
      <geometry>
        <mesh
          filename="package://manip/meshes/base_link.STL" />
      </geometry>
      <material
        name="">
        <color
          rgba="0.79216 0.81961 0.93333 1" />
      </material>
    </visual>
    <collision>
      <origin
        xyz="0 0 0"
        rpy="0 0 0" />
      <geometry>
        <mesh
          filename="package://manip/meshes/base_link.STL" />
      </geometry>
    </collision>
  </link>
  <link
    name="link_1">
    <inertial>
      <origin
        xyz="1.0128E-13 0.020714 0.11263"
        rpy="0 0 0" />
      <mass
        value="7.1545" />
      <inertia
        ixx="0.031384"
        ixy="-5.6746E-16"
        ixz="-1.9827E-14"
        iyy="0.032535"
        iyz="-0.0018984"
        izz="0.0071742" />
    </inertial>
    <visual>
      <origin
        xyz="0 0 0"
        rpy="0 0 0" />
      <geometry>
        <mesh
          filename="package://manip/meshes/link_1.STL" />
      </geometry>
      <material
        name="">
        <color
          rgba="0.79216 0.81961 0.93333 1" />
      </material>
    </visual>
    <collision>
      <origin
        xyz="0 0 0"
        rpy="0 0 0" />
      <geometry>
        <mesh
          filename="package://manip/meshes/link_1.STL" />
      </geometry>
    </collision>
  </link>
  <joint
    name="joint_1" type="revolute">
    <origin xyz="0 0 0" rpy="0 0 0" />
    <parent link="base_link" />
    <child link="link_1" />
    <axis xyz="0 0 1" />
    <limit lower="-3.14" upper="3.14" effort="500" velocity="0.1" />
  </joint>
  
  <!--  -->
  <transmission name="transmission_base_link_to_lin_1">
  	<type>transmission_interface/SimlpeTransmission</type> <!-- Простая редукторная передача - связывает один двигатель с одним интерфейсом -->
  	<joint name="joint_1"> <!-- Указываем сочленение, для которого мы используем эту трансмиссию -->
  		<hardwareInterface>hardware_interface/EffortJointInterface</hardwareInterface>
  	</joint>
  	<actuator name="motor_joint_1">
  		<hardwareInterface>hardware_interface/EffortJointInterface</hardwareInterface>
  		<mechanicalReduction>3</mechanicalReduction> <!-- Указываем передаточное число (не должно быть нулём) -->
  	</actuator>
  </transmission>
    
  
  <link
    name="link_2">
    <inertial>
      <origin
        xyz="1.7513E-13 -0.025603 0.14965"
        rpy="0 0 0" />
      <mass
        value="4.2652" />
      <inertia
        ixx="0.0081437"
        ixy="8.9751E-18"
        ixz="-7.1536E-19"
        iyy="0.0094816"
        iyz="0.00010383"
        izz="0.0030776" />
    </inertial>
    <visual>
      <origin
        xyz="0 0 0"
        rpy="0 0 0" />
      <geometry>
        <mesh
          filename="package://manip/meshes/link_2.STL" />
      </geometry>
      <material
        name="">
        <color
          rgba="0.79216 0.81961 0.93333 1" />
      </material>
    </visual>
    <collision>
      <origin
        xyz="0 0 0"
        rpy="0 0 0" />
      <geometry>
        <mesh
          filename="package://manip/meshes/link_2.STL" />
      </geometry>
    </collision>
  </link>
  <joint
    name="joint_2"
    type="revolute">
    <origin
      xyz="0 0 0"
      rpy="0 0 0" />
    <parent
      link="link_1" />
    <child
      link="link_2" />
    <axis
      xyz="0 0 0" />
    <limit
      lower="0"
      upper="0"
      effort="0"
      velocity="0" />
  </joint>
  
  <!-- Добавляем плагин Gazebo_ROS_Control -->
  <gazebo>
  	<plugin name="gazebo_ros_control" filename="libgazebo_ros_control.so">
  		<robotNamespace>manip</robotNamespace> <!-- В этом неймспейсе будут отображаться все наши ноды и контроллера -->
  	</plugin>
  </gazebo>
</robot>
